Workbook

Sheet Partner Competency Input
A1: Partner & Person | E1: Platform 1 | I1: Platform 2 | M1: Platform 3 | Q1: Platform 4 | U1: Platform 5 | Y1: Platform 6 | AC1: Platform 7 | AG1: Platform 8 | AK1: Platform 9 | AO1: Platform 10 | AS1: Platform 11 | AW1: Certificates
A2: Partner Name | B2: Person Name | C2: Partner Program Tier | D2: Region | E2: Platform 1 | F2: Present | G2: Demo | H2: POC | I2: Platform 2 | J2: Present | K2: Demo | L2: POC | M2: Platform 3 | N2: Present | O2: Demo | P2: POC | Q2: Platform 4 | R2: Present | S2: Demo | T2: POC | U2: Platform 5 | V2: Present | W2: Demo | X2: POC | Y2: Platform 6 | Z2: Present | AA2: Demo | AB2: POC | AC2: Platform 7 | AD2: Present | AE2: Demo | AF2: POC | AG2: Platform 8 | AH2: Present | AI2: Demo | AJ2: POC | AK2: Platform 9 | AL2: Present | AM2: Demo | AN2: POC | AO2: Platform 10 | AP2: Present | AQ2: Demo | AR2: POC | AS2: Platform 11 | AT2: Present | AU2: Demo | AV2: POC | AW2: PACSE | AX2: SE Expert | AY2: Threat Protection Administrator | AZ2: Threat Protection Analyst | BA2: Data Protection Administrator | BB2: Data Protection Analyst | BC2: SE Champion | BD2: Health Check Certified
A4: Nextgen | B4: Vikesh Ramnath | C4: Elite+ | D4: Australia | E4: Email Gateway | F4: Yes | G4: Yes | H4: No | I4: TAP | J4: Yes | K4: Yes | L4: No | M4: TRAP | N4: Yes | O4: Yes | P4: No | Q4: Isolation | R4: Yes | S4: Yes | T4: No | U4: Zenguide | V4: Yes | W4: Yes | X4: Yes | Y4: ITM | Z4: Yes | AA4: Yes | AB4: No | AC4: Endpoint DLP | AD4: Yes | AE4: Yes | AF4: No | AG4: CASB | AH4: Yes | AI4: Yes | AJ4: No | AK4: Email DLP | AL4: Yes | AM4: Yes | AN4: No | AO4: AEDLP | AP4: Yes | AQ4: Yes | AR4: Yes | AS4: CEPAPI | AT4: Yes | AU4: Yes | AV4: Yes | AW4: Yes | AX4: Yes | AY4: Yes | AZ4: Yes | BA4: No | BB4: No | BC4: Yes | BD4: Yes
A5: Ingram Micro | B5: Wesley Hwang | C5: Elite+ | D5: Australia | E5: Email Gateway | F5: Yes | G5: Yes | H5: No | I5: TAP | J5: Yes | K5: Yes | L5: No | M5: TRAP | N5: Yes | O5: Yes | P5: No | Q5: Isolation | R5: Yes | S5: Yes | T5: No | U5: Zenguide | V5: Yes | W5: Yes | X5: Yes | Y5: ITM | Z5: Yes | AA5: Yes | AB5: No | AC5: Endpoint DLP | AD5: Yes | AE5: Yes | AF5: No | AG5: CASB | AH5: Yes | AI5: Yes | AJ5: No | AK5: Email DLP | AL5: Yes | AM5: Yes | AN5: No | AO5: AEDLP | AP5: Yes | AQ5: Yes | AR5: Yes | AS5: CEPAPI | AT5: Yes | AU5: Yes | AV5: Yes | AW5: Yes | AX5: Yes | AY5: Yes | AZ5: Yes | BA5: No | BB5: No | BC5: Yes | BD5: Yes
A6: Lumen IT | B6: Craig Tamlin | C6: Elite+ | D6: Australia | E6: Email Gateway | F6: Yes | G6: Yes | H6: No | I6: TAP | J6: Yes | K6: Yes | L6: No | M6: TRAP | N6: Yes | O6: Yes | P6: No | Q6: Isolation | R6: Yes | S6: Yes | T6: No | U6: Zenguide | V6: Yes | W6: Yes | X6: Yes | Y6: ITM | Z6: Yes | AA6: Yes | AB6: No | AC6: Endpoint DLP | AD6: Yes | AE6: Yes | AF6: No | AG6: CASB | AH6: Yes | AI6: Yes | AJ6: No | AK6: Email DLP | AL6: Yes | AM6: Yes | AN6: No | AO6: AEDLP | AP6: Yes | AQ6: Yes | AR6: Yes | AS6: CEPAPI | AT6: Yes | AU6: Yes | AV6: Yes | AW6: Yes | AX6: Yes | AY6: No | AZ6: No | BA6: No | BB6: No | BC6: Yes | BD6: Yes
A7: Lumen IT | B7: Andy Tamin | C7: Elite+ | D7: Australia | E7: Email Gateway | F7: Yes | G7: Yes | H7: No | I7: TAP | J7: Yes | K7: Yes | L7: No | M7: TRAP | N7: Yes | O7: Yes | P7: No | Q7: Isolation | R7: Yes | S7: Yes | T7: No | U7: Zenguide | V7: Yes | W7: Yes | X7: Yes | Y7: ITM | Z7: Yes | AA7: Yes | AB7: No | AC7: Endpoint DLP | AD7: Yes | AE7: Yes | AF7: No | AG7: CASB | AH7: Yes | AI7: Yes | AJ7: No | AK7: Email DLP | AL7: Yes | AM7: Yes | AN7: No | AO7: AEDLP | AP7: Yes | AQ7: Yes | AR7: Yes | AS7: CEPAPI | AT7: Yes | AU7: Yes | AV7: Yes | AW7: Yes | AX7: Yes | AY7: No | AZ7: No | BA7: No | BB7: No | BC7: Yes | BD7: Yes
A8: NTT Australia | B8: Ali Shayan | C8: Elite+ | D8: Australia | E8: Email Gateway | F8: Yes | G8: Yes | H8: No | I8: TAP | J8: Yes | K8: Yes | L8: No | M8: TRAP | N8: Yes | O8: Yes | P8: No | Q8: Isolation | R8: Yes | S8: Yes | T8: No | U8: Zenguide | V8: Yes | W8: Yes | X8: Yes | Y8: ITM | Z8: Yes | AA8: Yes | AB8: No | AC8: Endpoint DLP | AD8: Yes | AE8: Yes | AF8: No | AG8: CASB | AH8: Yes | AI8: Yes | AJ8: No | AK8: Email DLP | AL8: Yes | AM8: Yes | AN8: No | AO8: AEDLP | AP8: Yes | AQ8: Yes | AR8: Yes | AS8: CEPAPI | AT8: Yes | AU8: Yes | AV8: Yes | AW8: Yes | AX8: Yes | AY8: No | AZ8: No | BA8: No | BB8: No | BC8: Yes | BD8: Yes
A9: NTT Australia | B9: Diwei Wang | C9: Elite+ | D9: Australia | E9: Email Gateway | F9: Yes | G9: Yes | H9: No | I9: TAP | J9: Yes | K9: Yes | L9: No | M9: TRAP | N9: Yes | O9: Yes | P9: No | Q9: Isolation | R9: Yes | S9: Yes | T9: No | U9: Zenguide | V9: Yes | W9: Yes | X9: Yes | Y9: ITM | Z9: Yes | AA9: Yes | AB9: No | AC9: Endpoint DLP | AD9: Yes | AE9: Yes | AF9: No | AG9: CASB | AH9: Yes | AI9: Yes | AJ9: No | AK9: Email DLP | AL9: Yes | AM9: Yes | AN9: No | AO9: AEDLP | AP9: Yes | AQ9: Yes | AR9: Yes | AS9: CEPAPI | AT9: Yes | AU9: Yes | AV9: Yes | AW9: Yes | AX9: Yes | AY9: No | AZ9: No | BA9: No | BB9: No | BC9: Yes | BD9: Yes
A10: NTT Australia | B10: Frank Murdica | C10: Elite+ | D10: Australia | E10: Email Gateway | F10: Yes | G10: Yes | H10: No | I10: TAP | J10: Yes | K10: Yes | L10: No | M10: TRAP | N10: Yes | O10: Yes | P10: No | Q10: Isolation | R10: Yes | S10: Yes | T10: No | U10: Zenguide | V10: Yes | W10: Yes | X10: Yes | Y10: ITM | Z10: Yes | AA10: Yes | AB10: No | AC10: Endpoint DLP | AD10: Yes | AE10: Yes | AF10: No | AG10: CASB | AH10: Yes | AI10: Yes | AJ10: No | AK10: Email DLP | AL10: Yes | AM10: Yes | AN10: No | AO10: AEDLP | AP10: Yes | AQ10: Yes | AR10: Yes | AS10: CEPAPI | AT10: Yes | AU10: Yes | AV10: Yes | AW10: Yes | AX10: Yes | AY10: No | AZ10: No | BA10: No | BB10: No | BC10: Yes | BD10: Yes
A11: NTT Australia | B11: Suraj Panicker | C11: Elite+ | D11: Australia | E11: Email Gateway | F11: Yes | G11: Yes | H11: No | I11: TAP | J11: Yes | K11: Yes | L11: No | M11: TRAP | N11: Yes | O11: Yes | P11: No | Q11: Isolation | R11: Yes | S11: Yes | T11: No | U11: Zenguide | V11: Yes | W11: Yes | X11: Yes | Y11: ITM | Z11: Yes | AA11: Yes | AB11: No | AC11: Endpoint DLP | AD11: Yes | AE11: Yes | AF11: No | AG11: CASB | AH11: Yes | AI11: Yes | AJ11: No | AK11: Email DLP | AL11: Yes | AM11: Yes | AN11: No | AO11: AEDLP | AP11: Yes | AQ11: Yes | AR11: Yes | AS11: CEPAPI | AT11: Yes | AU11: Yes | AV11: Yes | AW11: Yes | AX11: Yes | AY11: No | AZ11: No | BA11: No | BB11: No | BC11: Yes | BD11: Yes
A12: NTT Australia | B12: Kaushal Patel | C12: Elite+ | D12: Australia | E12: Email Gateway | F12: Yes | G12: Yes | H12: No | I12: TAP | J12: Yes | K12: Yes | L12: No | M12: TRAP | N12: Yes | O12: Yes | P12: No | Q12: Isolation | R12: Yes | S12: Yes | T12: No | U12: Zenguide | V12: Yes | W12: Yes | X12: Yes | Y12: ITM | Z12: Yes | AA12: Yes | AB12: No | AC12: Endpoint DLP | AD12: Yes | AE12: Yes | AF12: No | AG12: CASB | AH12: Yes | AI12: Yes | AJ12: No | AK12: Email DLP | AL12: Yes | AM12: Yes | AN12: No | AO12: AEDLP | AP12: Yes | AQ12: Yes | AR12: Yes | AS12: CEPAPI | AT12: Yes | AU12: Yes | AV12: Yes | AW12: Yes | AX12: Yes | AY12: No | AZ12: No | BA12: No | BB12: No | BC12: Yes | BD12: Yes
A13: NTT Australia | B13: Ronit Pradhan | C13: Elite+ | D13: Australia | E13: Email Gateway | F13: Yes | G13: Yes | H13: No | I13: TAP | J13: Yes | K13: Yes | L13: No | M13: TRAP | N13: Yes | O13: Yes | P13: No | Q13: Isolation | R13: Yes | S13: Yes | T13: No | U13: Zenguide | V13: Yes | W13: Yes | X13: Yes | Y13: ITM | Z13: Yes | AA13: Yes | AB13: No | AC13: Endpoint DLP | AD13: Yes | AE13: Yes | AF13: No | AG13: CASB | AH13: Yes | AI13: Yes | AJ13: No | AK13: Email DLP | AL13: Yes | AM13: Yes | AN13: No | AO13: AEDLP | AP13: Yes | AQ13: Yes | AR13: Yes | AS13: CEPAPI | AT13: Yes | AU13: Yes | AV13: Yes | AW13: Yes | AX13: Yes | AY13: No | AZ13: No | BA13: No | BB13: No | BC13: Yes | BD13: Yes
A14: NTT Australia | B14: Umar Shafqat | C14: Elite+ | D14: Australia | E14: Email Gateway | F14: Yes | G14: Yes | H14: No | I14: TAP | J14: Yes | K14: Yes | L14: No | M14: TRAP | N14: Yes | O14: Yes | P14: No | Q14: Isolation | R14: Yes | S14: Yes | T14: No | U14: Zenguide | V14: Yes | W14: Yes | X14: Yes | Y14: ITM | Z14: Yes | AA14: Yes | AB14: No | AC14: Endpoint DLP | AD14: Yes | AE14: Yes | AF14: No | AG14: CASB | AH14: Yes | AI14: Yes | AJ14: No | AK14: Email DLP | AL14: Yes | AM14: Yes | AN14: No | AO14: AEDLP | AP14: Yes | AQ14: Yes | AR14: Yes | AS14: CEPAPI | AT14: Yes | AU14: Yes | AV14: Yes | AW14: Yes | AX14: Yes | AY14: No | AZ14: No | BA14: No | BB14: No | BC14: Yes | BD14: Yes
... A26: Infotrust | B26: Richard Dobson | C26: Elite+ | D26: Australia | E26: Email Gateway | F26: Yes | G26: Yes | H26: No | I26: TAP | J26: Yes | K26: Yes | L26: No | M26: TRAP | N26: Yes | O26: Yes | P26: No | Q26: Isolation | R26: Yes | S26: Yes | T26: No | U26: Zenguide | V26: Yes | W26: Yes | X26: Yes | Y26: ITM | Z26: Yes | AA26: Yes | AB26: No | AC26: Endpoint DLP | AD26: Yes | AE26: Yes | AF26: No | AG26: CASB | AH26: Yes | AI26: Yes | AJ26: No | AK26: Email DLP | AL26: Yes | AM26: Yes | AN26: No | AO26: AEDLP | AP26: Yes | AQ26: Yes | AR26: Yes | AS26: CEPAPI | AT26: Yes | AU26: Yes | AV26: Yes | AW26: Yes | AX26: Yes | AY26: Yes | AZ26: No | BA26: No | BB26: No | BC26: Yes | BD26: Yes
A27: Cyberintelsys | D27: India | E27: Email Gateway | I27: TAP | M27: TRAP | Q27: Isolation | U27: Zenguide | Y27: ITM | AC27: Endpoint DLP | AG27: CASB | AK27: Email DLP | AO27: AEDLP | AS27: CEPAPI
A28: Hitachi Systems Ind Pvt Ltd | D28: India | E28: Email Gateway | I28: TAP | M28: TRAP | Q28: Isolation | U28: Zenguide | Y28: ITM | AC28: Endpoint DLP | AG28: CASB | AK28: Email DLP | AO28: AEDLP | AS28: CEPAPI
A29: Esecforte | B29: Deep Shankar | D29: India | E29: Email Gateway | F29: Yes | G29: Yes | H29: Yes | I29: TAP | J29: Yes | K29: Yes | L29: Yes | M29: TRAP | N29: Yes | O29: Yes | P29: Yes | Q29: Isolation | R29: Yes | S29: Yes | T29: Yes | U29: Zenguide | V29: Yes | W29: Yes | X29: Yes | Y29: ITM | Z29: Yes | AA29: Yes | AB29: Yes | AC29: Endpoint DLP | AD29: Yes | AE29: Yes | AF29: Yes | AG29: CASB | AH29: Yes | AI29: Yes | AJ29: Yes | AK29: Email DLP | AL29: Yes | AM29: Yes | AN29: Yes | AO29: AEDLP | AS29: CEPAPI | AT29: Yes | AU29: Yes | AV29: Yes | AW29: Yes | AX29: Yes | BC29: Yes | BD29: Yes
A30: Esecforte | B30: Shefali Rajpal | D30: India | E30: Email Gateway | F30: Yes | G30: Yes | H30: Yes | I30: TAP | J30: Yes | K30: Yes | L30: Yes | M30: TRAP | N30: Yes | O30: Yes | P30: Yes | Q30: Isolation | R30: Yes | S30: Yes | T30: Yes | U30: Zenguide | V30: Yes | W30: Yes | X30: No | Y30: ITM | Z30: Yes | AA30: Yes | AB30: Yes | AC30: Endpoint DLP | AD30: Yes | AE30: Yes | AF30: Yes | AG30: CASB | AH30: Yes | AI30: Yes | AJ30: Yes | AK30: Email DLP | AL30: Yes | AM30: Yes | AN30: Yes | AO30: AEDLP | AS30: CEPAPI | AT30: Yes | AU30: Yes | AV30: Yes | AW30: Yes | AX30: Yes | BC30: Yes | BD30: Yes
A31: Esecforte | B31: Dhruv Rawat | D31: India | E31: Email Gateway | F31: Yes | G31: Yes | H31: No | I31: TAP | J31: Yes | K31: No | L31: No | M31: TRAP | N31: Yes | O31: No | P31: No | Q31: Isolation | R31: Yes | S31: No | T31: No | U31: Zenguide | V31: No | W31: No | X31: No | Y31: ITM | Z31: No | AA31: No | AB31: No | AC31: Endpoint DLP | AD31: No | AE31: No | AF31: No | AG31: CASB | AH31: No | AI31: No | AJ31: No | AK31: Email DLP | AL31: No | AM31: No | AN31: No | AO31: AEDLP | AS31: CEPAPI | AT31: Yes | AU31: Yes | AV31: Yes
A32: Esecforte | B32: Siddharth Ram | D32: India | E32: Email Gateway | F32: Yes | G32: No | H32: No | I32: TAP | J32: Yes | K32: No | L32: No | M32: TRAP | N32: Yes | O32: No | P32: No | Q32: Isolation | R32: Yes | S32: No | T32: No | U32: Zenguide | V32: No | W32: No | X32: No | Y32: ITM | Z32: No | AA32: No | AB32: No | AC32: Endpoint DLP | AD32: No | AE32: No | AF32: No | AG32: CASB | AH32: No | AI32: No | AJ32: No | AK32: Email DLP | AL32: No | AM32: No | AN32: No | AO32: AEDLP | AS32: CEPAPI | AT32: Yes | AU32: Yes | AV32: Yes
A33: Cyberpwn | B33: Srinath VS | D33: India | E33: Email Gateway | F33: Yes | G33: Yes | H33: Yes | I33: TAP | J33: Yes | K33: Yes | L33: Yes | M33: TRAP | N33: Yes | O33: Yes | P33: Yes | Q33: Isolation | R33: Yes | S33: Yes | T33: Yes | U33: Zenguide | V33: Yes | W33: Yes | X33: Yes | Y33: ITM | Z33: Yes | AA33: Yes | AB33: Yes | AC33: Endpoint DLP | AD33: Yes | AE33: Yes | AF33: Yes | AG33: CASB | AH33: Yes | AI33: Yes | AJ33: Yes | AK33: Email DLP | AL33: Yes | AM33: Yes | AN33: Yes | AO33: AEDLP | AS33: CEPAPI | AT33: Yes | AU33: Yes | AV33: Yes | AW33: Yes | AX33: Yes | BC33: Yes | BD33: Yes
A34: Cyberpwn | B34: Prashant Nayak | D34: India | E34: Email Gateway | F34: Yes | G34: Yes | H34: Yes | I34: TAP | J34: Yes | K34: Yes | L34: Yes | M34: TRAP | N34: Yes | O34: Yes | P34: Yes | Q34: Isolation | R34: Yes | S34: Yes | T34: Yes | U34: Zenguide | V34: Yes | W34: Yes | X34: Yes | Y34: ITM | Z34: Yes | AA34: Yes | AB34: Yes | AC34: Endpoint DLP | AD34: Yes | AE34: Yes | AF34: Yes | AG34: CASB | AH34: Yes | AI34: Yes | AJ34: Yes | AK34: Email DLP | AL34: Yes | AM34: Yes | AN34: Yes | AO34: AEDLP | AS34: CEPAPI | AT34: Yes | AU34: Yes | AV34: Yes | AW34: Yes | AX34: Yes | BC34: Yes | BD34: Yes
A35: Cyberpwn | B35: Dona Thomas | D35: India | E35: Email Gateway | F35: Yes | G35: Yes | H35: Yes | I35: TAP | J35: Yes | K35: Yes | L35: Yes | M35: TRAP | N35: Yes | O35: Yes | P35: Yes | Q35: Isolation | R35: Yes | S35: Yes | T35: Yes | U35: Zenguide | V35: Yes | W35: Yes | X35: Yes | Y35: ITM | Z35: Yes | AA35: Yes | AB35: Yes | AC35: Endpoint DLP | AD35: Yes | AE35: Yes | AF35: Yes | AG35: CASB | AH35: Yes | AI35: Yes | AJ35: Yes | AK35: Email DLP | AL35: Yes | AM35: Yes | AN35: Yes | AO35: AEDLP | AS35: CEPAPI | AT35: Yes | AU35: Yes | AV35: Yes | AW35: Yes | AX35: Yes | BC35: Yes | BD35: Yes
A36: Cyberpwn | B36: Abdul Hameed | D36: India | E36: Email Gateway | F36: Yes | G36: Yes | H36: Yes | I36: TAP | J36: Yes | K36: Yes | L36: Yes | M36: TRAP | N36: Yes | O36: Yes | P36: Yes | Q36: Isolation | R36: Yes | S36: Yes | T36: Yes | U36: Zenguide | V36: Yes | W36: Yes | X36: Yes | Y36: ITM | Z36: Yes | AA36: Yes | AB36: Yes | AC36: Endpoint DLP | AD36: Yes | AE36: Yes | AF36: Yes | AG36: CASB | AH36: Yes | AI36: Yes | AJ36: Yes | AK36: Email DLP | AL36: Yes | AM36: Yes | AN36: Yes | AO36: AEDLP | AS36: CEPAPI | AT36: Yes | AU36: Yes | AV36: Yes | AW36: Yes | AX36: Yes | BC36: Yes | BD36: Yes
A37: Cyberpwn | B37: Dinesh Babu | D37: India | E37: Email Gateway | F37: Yes | G37: Yes | H37: Yes | I37: TAP | J37: Yes | K37: Yes | L37: Yes | M37: TRAP | N37: Yes | O37: Yes | P37: Yes | Q37: Isolation | R37: Yes | S37: Yes | T37: Yes | U37: Zenguide | V37: Yes | W37: Yes | X37: Yes | Y37: ITM | Z37: No | AA37: No | AB37: No | AC37: Endpoint DLP | AD37: No | AE37: No | AF37: No | AG37: CASB | AH37: No | AI37: No | AJ37: No | AK37: Email DLP | AL37: Yes | AM37: Yes | AN37: Yes | AO37: AEDLP | AS37: CEPAPI | AT37: Yes | AU37: Yes | AV37: Yes | AW37: Yes | AX37: Yes | BC37: Yes | BD37: Yes
A38: Cyberpwn | B38: Vishal Kumar | D38: India | E38: Email Gateway | F38: Yes | G38: Yes | H38: Yes | I38: TAP | J38: Yes | K38: Yes | L38: Yes | M38: TRAP | N38: Yes | O38: Yes | P38: Yes | Q38: Isolation | R38: Yes | S38: Yes | T38: Yes | U38: Zenguide | V38: Yes | W38: Yes | X38: Yes | Y38: ITM | Z38: Yes | AA38: Yes | AB38: Yes | AC38: Endpoint DLP | AD38: Yes | AE38: Yes | AF38: Yes | AG38: CASB | AH38: Yes | AI38: Yes | AJ38: Yes | AK38: Email DLP | AL38: Yes | AM38: Yes | AN38: Yes | AO38: AEDLP | AS38: CEPAPI | AT38: Yes | AU38: Yes | AV38: Yes | AW38: Yes | AX38: Yes | BC38: Yes | BD38: Yes
A39: Cyberpwn | B39: Ankush Zankar | D39: India | E39: Email Gateway | F39: Yes | G39: Yes | H39: No | I39: TAP | J39: Yes | K39: Yes | L39: No | M39: TRAP | N39: Yes | O39: Yes | P39: No | Q39: Isolation | R39: Yes | S39: Yes | T39: Yes | U39: Zenguide | V39: No | W39: No | X39: No | Y39: ITM | Z39: Yes | AA39: Yes | AB39: Yes | AC39: Endpoint DLP | AD39: Yes | AE39: Yes | AF39: Yes | AG39: CASB | AH39: Yes | AI39: Yes | AJ39: Yes | AK39: Email DLP | AL39: Yes | AM39: Yes | AN39: Yes | AO39: AEDLP | AS39: CEPAPI | AT39: Yes | AU39: Yes | AV39: Yes | AW39: Yes | AX39: Yes | BC39: Yes | BD39: Yes
A40: Cyberpwn | B40: Anuj Paratap | D40: India | E40: Email Gateway | F40: Yes | G40: Yes | H40: No | I40: TAP | J40: Yes | K40: Yes | L40: No | M40: TRAP | N40: Yes | O40: Yes | P40: No | Q40: Isolation | R40: Yes | S40: Yes | T40: Yes | U40: Zenguide | V40: No | W40: No | X40: No | Y40: ITM | Z40: Yes | AA40: Yes | AB40: Yes | AC40: Endpoint DLP | AD40: Yes | AE40: Yes | AF40: Yes | AG40: CASB | AH40: Yes | AI40: Yes | AJ40: Yes | AK40: Email DLP | AL40: Yes | AM40: Yes | AN40: Yes | AO40: AEDLP | AS40: CEPAPI | AT40: Yes | AU40: Yes | AV40: Yes | AW40: Yes | AX40: Yes | BC40: Yes | BD40: Yes
A41: Cyberpwn | B41: Shantanu Goswami | D41: India | E41: Email Gateway | F41: Yes | G41: Yes | H41: No | I41: TAP | J41: Yes | K41: Yes | L41: No | M41: TRAP | N41: Yes | O41: Yes | P41: No | Q41: Isolation | R41: Yes | S41: Yes | T41: Yes | U41: Zenguide | V41: No | W41: No | X41: No | Y41: ITM | Z41: Yes | AA41: Yes | AB41: Yes | AC41: Endpoint DLP | AD41: Yes | AE41: Yes | AF41: Yes | AG41: CASB | AH41: Yes | AI41: Yes | AJ41: Yes | AK41: Email DLP | AL41: Yes | AM41: Yes | AN41: Yes | AO41: AEDLP | AS41: CEPAPI | AT41: Yes | AU41: Yes | AV41: Yes | AW41: Yes | AX41: Yes | BC41: Yes | BD41: Yes
A42: Essen Vision | B42: Shruti Shetty | D42: India | E42: Email Gateway | F42: Yes | G42: Yes | H42: Yes | I42: TAP | J42: Yes | K42: Yes | L42: Yes | M42: TRAP | N42: Yes | O42: Yes | P42: Yes | Q42: Isolation | R42: Yes | S42: Yes | T42: Yes | U42: Zenguide | V42: No | W42: No | X42: No | Y42: ITM | Z42: Yes | AA42: Yes | AB42: Yes | AC42: Endpoint DLP | AD42: Yes | AE42: Yes | AF42: Yes | AG42: CASB | AH42: Yes | AI42: Yes | AJ42: Yes | AK42: Email DLP | AL42: Yes | AM42: Yes | AN42: Yes | AO42: AEDLP | AS42: CEPAPI | AW42: Yes | AX42: Yes | AY42: Yes | BA42: Yes | BC42: Yes | BD42: Yes
A43: Essen Vision | B43: Susheel Pandey | D43: India | E43: Email Gateway | F43: Yes | G43: Yes | H43: Yes | I43: TAP | J43: Yes | K43: Yes | L43: Yes | M43: TRAP | N43: Yes | O43: Yes | P43: Yes | Q43: Isolation | R43: Yes | S43: Yes | T43: Yes | U43: Zenguide | V43: No | W43: No | X43: No | Y43: ITM | Z43: Yes | AA43: Yes | AB43: Yes | AC43: Endpoint DLP | AD43: Yes | AE43: Yes | AF43: Yes | AG43: CASB | AH43: Yes | AI43: Yes | AJ43: Yes | AK43: Email DLP | AL43: Yes | AM43: Yes | AN43: Yes | AO43: AEDLP | AS43: CEPAPI | AW43: Yes | AX43: Yes | BC43: Yes | BD43: Yes
A44: Essen Vision | D44: India | E44: Email Gateway | I44: TAP | M44: TRAP | Q44: Isolation | U44: Zenguide | Y44: ITM | AC44: Endpoint DLP | AG44: CASB | AK44: Email DLP | AO44: AEDLP | AS44: CEPAPI
A45: Essen Vision | D45: India | E45: Email Gateway | I45: TAP | M45: TRAP | Q45: Isolation | U45: Zenguide | Y45: ITM | AC45: Endpoint DLP | AG45: CASB | AK45: Email DLP | AO45: AEDLP | AS45: CEPAPI
A46: Meta Infotech | B46: Aishwarya Vijay | D46: India | E46: Email Gateway | F46: Yes | G46: Yes | H46: Yes | I46: TAP | J46: Yes | K46: Yes | L46: Yes | M46: TRAP | N46: Yes | O46: Yes | P46: Yes | Q46: Isolation | R46: Yes | S46: Yes | T46: Yes | U46: Zenguide | V46: Yes | W46: Yes | X46: Yes | Y46: ITM | Z46: Yes | AA46: Yes | AB46: Yes | AC46: Endpoint DLP | AD46: Yes | AE46: Yes | AF46: Yes | AG46: CASB | AH46: Yes | AI46: Yes | AJ46: Yes | AK46: Email DLP | AL46: Yes | AM46: Yes | AN46: Yes | AO46: AEDLP | AS46: CEPAPI | AT46: Yes | AU46: Yes | AV46: Yes | AW46: Yes | AX46: Yes | BC46: Yes | BD46: Yes
A47: Meta Infotech | B47: Lalit Dureja | D47: India | E47: Email Gateway | F47: Yes | G47: Yes | H47: Yes | I47: TAP | J47: Yes | K47: Yes | L47: Yes | M47: TRAP | N47: Yes | O47: Yes | P47: Yes | Q47: Isolation | R47: Yes | S47: Yes | T47: Yes | U47: Zenguide | V47: Yes | W47: Yes | X47: Yes | Y47: ITM | Z47: Yes | AA47: Yes | AB47: Yes | AC47: Endpoint DLP | AD47: Yes | AE47: Yes | AF47: Yes | AG47: CASB | AH47: Yes | AI47: Yes | AJ47: Yes | AK47: Email DLP | AL47: Yes | AM47: Yes | AN47: Yes | AO47: AEDLP | AS47: CEPAPI | AT47: Yes | AU47: Yes | AV47: Yes | AW47: Yes | AX47: Yes | BC47: Yes | BD47: Yes
A48: Meta Infotech | B48: Kishore Achuthani | D48: India | E48: Email Gateway | F48: Yes | G48: Yes | H48: Yes | I48: TAP | J48: Yes | K48: Yes | L48: Yes | M48: TRAP | N48: Yes | O48: Yes | P48: Yes | Q48: Isolation | R48: Yes | S48: Yes | T48: Yes | U48: Zenguide | V48: Yes | W48: Yes | X48: Yes | Y48: ITM | Z48: Yes | AA48: Yes | AB48: Yes | AC48: Endpoint DLP | AD48: Yes | AE48: Yes | AF48: Yes | AG48: CASB | AH48: Yes | AI48: Yes | AJ48: Yes | AK48: Email DLP | AL48: Yes | AM48: Yes | AN48: Yes | AO48: AEDLP | AS48: CEPAPI | AT48: Yes | AU48: Yes | AV48: Yes | AW48: Yes | AX48: Yes | BC48: Yes | BD48: Yes
A49: Meta Infotech | B49: Krishna Modekurty | D49: India | E49: Email Gateway | F49: Yes | G49: Yes | H49: Yes | I49: TAP | J49: Yes | K49: Yes | L49: Yes | M49: TRAP | N49: Yes | O49: Yes | P49: Yes | Q49: Isolation | R49: Yes | S49: Yes | T49: Yes | U49: Zenguide | V49: Yes | W49: Yes | X49: Yes | Y49: ITM | Z49: Yes | AA49: Yes | AB49: Yes | AC49: Endpoint DLP | AD49: Yes | AE49: Yes | AF49: Yes | AG49: CASB | AH49: Yes | AI49: Yes | AJ49: Yes | AK49: Email DLP | AL49: Yes | AM49: Yes | AN49: Yes | AO49: AEDLP | AS49: CEPAPI | AT49: Yes | AU49: Yes | AV49: Yes | AW49: Yes | AX49: Yes | BC49: Yes | BD49: Yes
A50: Meta Infotech | B50: Poonam Tilekar | D50: India | E50: Email Gateway | F50: Yes | G50: Yes | H50: Yes | I50: TAP | J50: Yes | K50: Yes | L50: Yes | M50: TRAP | N50: Yes | O50: Yes | P50: Yes | Q50: Isolation | R50: Yes | S50: Yes | T50: Yes | U50: Zenguide | V50: Yes | W50: Yes | X50: Yes | Y50: ITM | Z50: Yes | AA50: Yes | AB50: Yes | AC50: Endpoint DLP | AD50: Yes | AE50: Yes | AF50: Yes | AG50: CASB | AH50: Yes | AI50: Yes | AJ50: Yes | AK50: Email DLP | AL50: Yes | AM50: Yes | AN50: Yes | AO50: AEDLP | AS50: CEPAPI | AT50: Yes | AU50: Yes | AV50: Yes | AW50: Yes | AX50: Yes | BC50: Yes | BD50: Yes
A51: Meta Infotech | B51: Sandeep Rao | D51: India | E51: Email Gateway | F51: Yes | G51: Yes | H51: Yes | I51: TAP | J51: Yes | K51: Yes | L51: Yes | M51: TRAP | N51: Yes | O51: Yes | P51: Yes | Q51: Isolation | R51: Yes | S51: Yes | T51: Yes | U51: Zenguide | V51: Yes | W51: Yes | X51: Yes | Y51: ITM | Z51: Yes | AA51: Yes | AB51: Yes | AC51: Endpoint DLP | AD51: Yes | AE51: Yes | AF51: Yes | AG51: CASB | AH51: Yes | AI51: Yes | AJ51: Yes | AK51: Email DLP | AL51: Yes | AM51: Yes | AN51: Yes | AO51: AEDLP | AS51: CEPAPI | AT51: Yes | AU51: Yes | AV51: Yes | AW51: Yes | AX51: Yes | BC51: Yes | BD51: Yes
A52: Meta Infotech | B52: Shruti Shinday | D52: India | E52: Email Gateway | F52: Yes | G52: Yes | H52: Yes | I52: TAP | J52: Yes | K52: Yes | L52: Yes | M52: TRAP | N52: Yes | O52: Yes | P52: Yes | Q52: Isolation | R52: Yes | S52: Yes | T52: Yes | U52: Zenguide | V52: Yes | W52: Yes | X52: Yes | Y52: ITM | Z52: Yes | AA52: Yes | AB52: Yes | AC52: Endpoint DLP | AD52: Yes | AE52: Yes | AF52: Yes | AG52: CASB | AH52: Yes | AI52: Yes | AJ52: Yes | AK52: Email DLP | AL52: Yes | AM52: Yes | AN52: Yes | AO52: AEDLP | AS52: CEPAPI | AT52: Yes | AU52: Yes | AV52: Yes | AW52: Yes | AX52: Yes | BC52: Yes | BD52: Yes
...

Sheet Lists
A1: Platforms | B1: Regions | C1: YesNo | D1: Partner Program Tier
A2: Email Gateway | B2: Australia | C2: Yes | D2: Select
A3: TAP | B3: New Zealand | C3: No | D3: Elite
A4: TRAP | B4: India | D4: Elite+
A5: Isolation | B5: Japan
A6: Zenguide | B6: Singapore
A7: EFD | B7: Hong Kong
A8: SER | B8: Thailand
A9: ITM | B9: Philippines
A10: Endpoint DLP | B10: Malaysia
A11: CASB | B11: Indonesia
A12: Email DLP | B12: Korea
A13: DSPM | B13: Taiwan
A14: AEDLP | B14: Vietnam
A15: CEPAPI

Sheet Instructions
A1: Partner Competency Dashboard – Instructions
A2: Use one row per person in Partner Competency Input.
A3: For each platform slot, choose the platform and then mark Present, Demo, and POC separately.
A4: If a person cannot drive POC for a platform, leave that POC cell blank or select No for that platform only.
A5: Certificates use Yes / No dropdowns.
A6: All Platforms combines the platform names only.
A7: Heatmap Dashboard counts distinct people for each Partner × Platform × Capability using the input sheet as the source of truth.

Sheet Normalized
A1: Partner Name | B1: Person Name | C1: Region | D1: Platform | E1: Present | F1: Demo | G1: POC
A2: =IF('Partner Competency Input'!E4<>"",'Partner Competency Input'!$A$4,"") -> Nextgen | B2: =IF('Partner Competency Input'!E4<>"",'Partner Competency Input'!$B$4,"") -> Vikesh Ramnath | C2: =IF('Partner Competency Input'!E4<>"",'Partner Competency Input'!$D$4,"") -> Australia | D2: ='Partner Competency Input'!E4 -> Email Gateway | E2: ='Partner Competency Input'!F4 -> Yes | F2: ='Partner Competency Input'!G4 -> Yes | G2: ='Partner Competency Input'!H4 -> No
A3: =IF('Partner Competency Input'!I4<>"",'Partner Competency Input'!$A$4,"") -> Nextgen | B3: =IF('Partner Competency Input'!I4<>"",'Partner Competency Input'!$B$4,"") -> Vikesh Ramnath | C3: =IF('Partner Competency Input'!I4<>"",'Partner Competency Input'!$D$4,"") -> Australia | D3: ='Partner Competency Input'!I4 -> TAP | E3: ='Partner Competency Input'!J4 -> Yes | F3: ='Partner Competency Input'!K4 -> Yes | G3: ='Partner Competency Input'!L4 -> No
A4: =IF('Partner Competency Input'!M4<>"",'Partner Competency Input'!$A$4,"") -> Nextgen | B4: =IF('Partner Competency Input'!M4<>"",'Partner Competency Input'!$B$4,"") -> Vikesh Ramnath | C4: =IF('Partner Competency Input'!M4<>"",'Partner Competency Input'!$D$4,"") -> Australia | D4: ='Partner Competency Input'!M4 -> TRAP | E4: ='Partner Competency Input'!N4 -> Yes | F4: ='Partner Competency Input'!O4 -> Yes | G4: ='Partner Competency Input'!P4 -> No
A5: =IF('Partner Competency Input'!Q4<>"",'Partner Competency Input'!$A$4,"") -> Nextgen | B5: =IF('Partner Competency Input'!Q4<>"",'Partner Competency Input'!$B$4,"") -> Vikesh Ramnath | C5: =IF('Partner Competency Input'!Q4<>"",'Partner Competency Input'!$D$4,"") -> Australia | D5: ='Partner Competency Input'!Q4 -> Isolation | E5: ='Partner Competency Input'!R4 -> Yes | F5: ='Partner Competency Input'!S4 -> Yes | G5: ='Partner Competency Input'!T4 -> No
A6: =IF('Partner Competency Input'!U4<>"",'Partner Competency Input'!$A$4,"") -> Nextgen | B6: =IF('Partner Competency Input'!U4<>"",'Partner Competency Input'!$B$4,"") -> Vikesh Ramnath | C6: =IF('Partner Competency Input'!U4<>"",'Partner Competency Input'!$D$4,"") -> Australia | D6: ='Partner Competency Input'!U4 -> Zenguide | E6: ='Partner Competency Input'!V4 -> Yes | F6: ='Partner Competency Input'!W4 -> Yes | G6: ='Partner Competency Input'!X4 -> Yes
A7: =IF('Partner Competency Input'!Y4<>"",'Partner Competency Input'!$A$4,"") -> Nextgen | B7: =IF('Partner Competency Input'!Y4<>"",'Partner Competency Input'!$B$4,"") -> Vikesh Ramnath | C7: =IF('Partner Competency Input'!Y4<>"",'Partner Competency Input'!$D$4,"") -> Australia | D7: ='Partner Competency Input'!Y4 -> ITM | E7: ='Partner Competency Input'!Z4 -> Yes | F7: ='Partner Competency Input'!AA4 -> Yes | G7: ='Partner Competency Input'!AB4 -> No
A8: =IF('Partner Competency Input'!AC4<>"",'Partner Competency Input'!$A$4,"") -> Nextgen | B8: =IF('Partner Competency Input'!AC4<>"",'Partner Competency Input'!$B$4,"") -> Vikesh Ramnath | C8: =IF('Partner Competency Input'!AC4<>"",'Partner Competency Input'!$D$4,"") -> Australia | D8: ='Partner Competency Input'!AC4 -> Endpoint DLP | E8: ='Partner Competency Input'!AD4 -> Yes | F8: ='Partner Competency Input'!AE4 -> Yes | G8: ='Partner Competency Input'!AF4 -> No
A9: =IF('Partner Competency Input'!AG4<>"",'Partner Competency Input'!$A$4,"") -> Nextgen | B9: =IF('Partner Competency Input'!AG4<>"",'Partner Competency Input'!$B$4,"") -> Vikesh Ramnath | C9: =IF('Partner Competency Input'!AG4<>"",'Partner Competency Input'!$D$4,"") -> Australia | D9: ='Partner Competency Input'!AG4 -> CASB | E9: ='Partner Competency Input'!AH4 -> Yes | F9: ='Partner Competency Input'!AI4 -> Yes | G9: ='Partner Competency Input'!AJ4 -> No
A10: =IF('Partner Competency Input'!AK4<>"",'Partner Competency Input'!$A$4,"") -> Nextgen | B10: =IF('Partner Competency Input'!AK4<>"",'Partner Competency Input'!$B$4,"") -> Vikesh Ramnath | C10: =IF('Partner Competency Input'!AK4<>"",'Partner Competency Input'!$D$4,"") -> Australia | D10: ='Partner Competency Input'!AK4 -> Email DLP | E10: ='Partner Competency Input'!AL4 -> Yes | F10: ='Partner Competency Input'!AM4 -> Yes | G10: ='Partner Competency Input'!AN4 -> No
A11: =IF('Partner Competency Input'!AO4<>"",'Partner Competency Input'!$A$4,"") -> Nextgen | B11: =IF('Partner Competency Input'!AO4<>"",'Partner Competency Input'!$B$4,"") -> Vikesh Ramnath | C11: =IF('Partner Competency Input'!AO4<>"",'Partner Competency Input'!$D$4,"") -> Australia | D11: ='Partner Competency Input'!AO4 -> AEDLP | E11: ='Partner Competency Input'!AP4 -> Yes | F11: ='Partner Competency Input'!AQ4 -> Yes | G11: ='Partner Competency Input'!AR4 -> Yes
A12: =IF('Partner Competency Input'!AS4<>"",'Partner Competency Input'!$A$4,"") -> Nextgen | B12: =IF('Partner Competency Input'!AS4<>"",'Partner Competency Input'!$B$4,"") -> Vikesh Ramnath | C12: =IF('Partner Competency Input'!AS4<>"",'Partner Competency Input'!$D$4,"") -> Australia | D12: ='Partner Competency Input'!AS4 -> CEPAPI | E12: ='Partner Competency Input'!AT4 -> Yes | F12: ='Partner Competency Input'!AU4 -> Yes | G12: ='Partner Competency Input'!AV4 -> Yes
A13: =IF('Partner Competency Input'!E5<>"",'Partner Competency Input'!$A$5,"") -> Ingram Micro | B13: =IF('Partner Competency Input'!E5<>"",'Partner Competency Input'!$B$5,"") -> Wesley Hwang | C13: =IF('Partner Competency Input'!E5<>"",'Partner Competency Input'!$D$5,"") -> Australia | D13: ='Partner Competency Input'!E5 -> Email Gateway | E13: ='Partner Competency Input'!F5 -> Yes | F13: ='Partner Competency Input'!G5 -> Yes | G13: ='Partner Competency Input'!H5 -> No
A14: =IF('Partner Competency Input'!I5<>"",'Partner Competency Input'!$A$5,"") -> Ingram Micro | B14: =IF('Partner Competency Input'!I5<>"",'Partner Competency Input'!$B$5,"") -> Wesley Hwang | C14: =IF('Partner Competency Input'!I5<>"",'Partner Competency Input'!$D$5,"") -> Australia | D14: ='Partner Competency Input'!I5 -> TAP | E14: ='Partner Competency Input'!J5 -> Yes | F14: ='Partner Competency Input'!K5 -> Yes | G14: ='Partner Competency Input'!L5 -> No
A15: =IF('Partner Competency Input'!M5<>"",'Partner Competency Input'!$A$5,"") -> Ingram Micro | B15: =IF('Partner Competency Input'!M5<>"",'Partner Competency Input'!$B$5,"") -> Wesley Hwang | C15: =IF('Partner Competency Input'!M5<>"",'Partner Competency Input'!$D$5,"") -> Australia | D15: ='Partner Competency Input'!M5 -> TRAP | E15: ='Partner Competency Input'!N5 -> Yes | F15: ='Partner Competency Input'!O5 -> Yes | G15: ='Partner Competency Input'!P5 -> No
A16: =IF('Partner Competency Input'!Q5<>"",'Partner Competency Input'!$A$5,"") -> Ingram Micro | B16: =IF('Partner Competency Input'!Q5<>"",'Partner Competency Input'!$B$5,"") -> Wesley Hwang | C16: =IF('Partner Competency Input'!Q5<>"",'Partner Competency Input'!$D$5,"") -> Australia | D16: ='Partner Competency Input'!Q5 -> Isolation | E16: ='Partner Competency Input'!R5 -> Yes | F16: ='Partner Competency Input'!S5 -> Yes | G16: ='Partner Competency Input'!T5 -> No
A17: =IF('Partner Competency Input'!U5<>"",'Partner Competency Input'!$A$5,"") -> Ingram Micro | B17: =IF('Partner Competency Input'!U5<>"",'Partner Competency Input'!$B$5,"") -> Wesley Hwang | C17: =IF('Partner Competency Input'!U5<>"",'Partner Competency Input'!$D$5,"") -> Australia | D17: ='Partner Competency Input'!U5 -> Zenguide | E17: ='Partner Competency Input'!V5 -> Yes | F17: ='Partner Competency Input'!W5 -> Yes | G17: ='Partner Competency Input'!X5 -> Yes
A18: =IF('Partner Competency Input'!Y5<>"",'Partner Competency Input'!$A$5,"") -> Ingram Micro | B18: =IF('Partner Competency Input'!Y5<>"",'Partner Competency Input'!$B$5,"") -> Wesley Hwang | C18: =IF('Partner Competency Input'!Y5<>"",'Partner Competency Input'!$D$5,"") -> Australia | D18: ='Partner Competency Input'!Y5 -> ITM | E18: ='Partner Competency Input'!Z5 -> Yes | F18: ='Partner Competency Input'!AA5 -> Yes | G18: ='Partner Competency Input'!AB5 -> No
A19: =IF('Partner Competency Input'!AC5<>"",'Partner Competency Input'!$A$5,"") -> Ingram Micro | B19: =IF('Partner Competency Input'!AC5<>"",'Partner Competency Input'!$B$5,"") -> Wesley Hwang | C19: =IF('Partner Competency Input'!AC5<>"",'Partner Competency Input'!$D$5,"") -> Australia | D19: ='Partner Competency Input'!AC5 -> Endpoint DLP | E19: ='Partner Competency Input'!AD5 -> Yes | F19: ='Partner Competency Input'!AE5 -> Yes | G19: ='Partner Competency Input'!AF5 -> No
A20: =IF('Partner Competency Input'!AG5<>"",'Partner Competency Input'!$A$5,"") -> Ingram Micro | B20: =IF('Partner Competency Input'!AG5<>"",'Partner Competency Input'!$B$5,"") -> Wesley Hwang | C20: =IF('Partner Competency Input'!AG5<>"",'Partner Competency Input'!$D$5,"") -> Australia | D20: ='Partner Competency Input'!AG5 -> CASB | E20: ='Partner Competency Input'!AH5 -> Yes | F20: ='Partner Competency Input'!AI5 -> Yes | G20: ='Partner Competency Input'!AJ5 -> No
A21: =IF('Partner Competency Input'!AK5<>"",'Partner Competency Input'!$A$5,"") -> Ingram Micro | B21: =IF('Partner Competency Input'!AK5<>"",'Partner Competency Input'!$B$5,"") -> Wesley Hwang | C21: =IF('Partner Competency Input'!AK5<>"",'Partner Competency Input'!$D$5,"") -> Australia | D21: ='Partner Competency Input'!AK5 -> Email DLP | E21: ='Partner Competency Input'!AL5 -> Yes | F21: ='Partner Competency Input'!AM5 -> Yes | G21: ='Partner Competency Input'!AN5 -> No
A22: =IF('Partner Competency Input'!AO5<>"",'Partner Competency Input'!$A$5,"") -> Ingram Micro | B22: =IF('Partner Competency Input'!AO5<>"",'Partner Competency Input'!$B$5,"") -> Wesley Hwang | C22: =IF('Partner Competency Input'!AO5<>"",'Partner Competency Input'!$D$5,"") -> Australia | D22: ='Partner Competency Input'!AO5 -> AEDLP | E22: ='Partner Competency Input'!AP5 -> Yes | F22: ='Partner Competency Input'!AQ5 -> Yes | G22: ='Partner Competency Input'!AR5 -> Yes
A23: =IF('Partner Competency Input'!AS5<>"",'Partner Competency Input'!$A$5,"") -> Ingram Micro | B23: =IF('Partner Competency Input'!AS5<>"",'Partner Competency Input'!$B$5,"") -> Wesley Hwang | C23: =IF('Partner Competency Input'!AS5<>"",'Partner Competency Input'!$D$5,"") -> Australia | D23: ='Partner Competency Input'!AS5 -> CEPAPI | E23: ='Partner Competency Input'!AT5 -> Yes | F23: ='Partner Competency Input'!AU5 -> Yes | G23: ='Partner Competency Input'!AV5 -> Yes
A24: =IF('Partner Competency Input'!E6<>"",'Partner Competency Input'!$A$6,"") -> Lumen IT | B24: =IF('Partner Competency Input'!E6<>"",'Partner Competency Input'!$B$6,"") -> Craig Tamlin | C24: =IF('Partner Competency Input'!E6<>"",'Partner Competency Input'!$D$6,"") -> Australia | D24: ='Partner Competency Input'!E6 -> Email Gateway | E24: ='Partner Competency Input'!F6 -> Yes | F24: ='Partner Competency Input'!G6 -> Yes | G24: ='Partner Competency Input'!H6 -> No
A25: =IF('Partner Competency Input'!I6<>"",'Partner Competency Input'!$A$6,"") -> Lumen IT | B25: =IF('Partner Competency Input'!I6<>"",'Partner Competency Input'!$B$6,"") -> Craig Tamlin | C25: =IF('Partner Competency Input'!I6<>"",'Partner Competency Input'!$D$6,"") -> Australia | D25: ='Partner Competency Input'!I6 -> TAP | E25: ='Partner Competency Input'!J6 -> Yes | F25: ='Partner Competency Input'!K6 -> Yes | G25: ='Partner Competency Input'!L6 -> No
A26: =IF('Partner Competency Input'!M6<>"",'Partner Competency Input'!$A$6,"") -> Lumen IT | B26: =IF('Partner Competency Input'!M6<>"",'Partner Competency Input'!$B$6,"") -> Craig Tamlin | C26: =IF('Partner Competency Input'!M6<>"",'Partner Competency Input'!$D$6,"") -> Australia | D26: ='Partner Competency Input'!M6 -> TRAP | E26: ='Partner Competency Input'!N6 -> Yes | F26: ='Partner Competency Input'!O6 -> Yes | G26: ='Partner Competency Input'!P6 -> No
A27: =IF('Partner Competency Input'!Q6<>"",'Partner Competency Input'!$A$6,"") -> Lumen IT | B27: =IF('Partner Competency Input'!Q6<>"",'Partner Competency Input'!$B$6,"") -> Craig Tamlin | C27: =IF('Partner Competency Input'!Q6<>"",'Partner Competency Input'!$D$6,"") -> Australia | D27: ='Partner Competency Input'!Q6 -> Isolation | E27: ='Partner Competency Input'!R6 -> Yes | F27: ='Partner Competency Input'!S6 -> Yes | G27: ='Partner Competency Input'!T6 -> No
A28: =IF('Partner Competency Input'!U6<>"",'Partner Competency Input'!$A$6,"") -> Lumen IT | B28: =IF('Partner Competency Input'!U6<>"",'Partner Competency Input'!$B$6,"") -> Craig Tamlin | C28: =IF('Partner Competency Input'!U6<>"",'Partner Competency Input'!$D$6,"") -> Australia | D28: ='Partner Competency Input'!U6 -> Zenguide | E28: ='Partner Competency Input'!V6 -> Yes | F28: ='Partner Competency Input'!W6 -> Yes | G28: ='Partner Competency Input'!X6 -> Yes
A29: =IF('Partner Competency Input'!Y6<>"",'Partner Competency Input'!$A$6,"") -> Lumen IT | B29: =IF('Partner Competency Input'!Y6<>"",'Partner Competency Input'!$B$6,"") -> Craig Tamlin | C29: =IF('Partner Competency Input'!Y6<>"",'Partner Competency Input'!$D$6,"") -> Australia | D29: ='Partner Competency Input'!Y6 -> ITM | E29: ='Partner Competency Input'!Z6 -> Yes | F29: ='Partner Competency Input'!AA6 -> Yes | G29: ='Partner Competency Input'!AB6 -> No
A30: =IF('Partner Competency Input'!AC6<>"",'Partner Competency Input'!$A$6,"") -> Lumen IT | B30: =IF('Partner Competency Input'!AC6<>"",'Partner Competency Input'!$B$6,"") -> Craig Tamlin | C30: =IF('Partner Competency Input'!AC6<>"",'Partner Competency Input'!$D$6,"") -> Australia | D30: ='Partner Competency Input'!AC6 -> Endpoint DLP | E30: ='Partner Competency Input'!AD6 -> Yes | F30: ='Partner Competency Input'!AE6 -> Yes | G30: ='Partner Competency Input'!AF6 -> No
A31: =IF('Partner Competency Input'!AG6<>"",'Partner Competency Input'!$A$6,"") -> Lumen IT | B31: =IF('Partner Competency Input'!AG6<>"",'Partner Competency Input'!$B$6,"") -> Craig Tamlin | C31: =IF('Partner Competency Input'!AG6<>"",'Partner Competency Input'!$D$6,"") -> Australia | D31: ='Partner Competency Input'!AG6 -> CASB | E31: ='Partner Competency Input'!AH6 -> Yes | F31: ='Partner Competency Input'!AI6 -> Yes | G31: ='Partner Competency Input'!AJ6 -> No
A32: =IF('Partner Competency Input'!AK6<>"",'Partner Competency Input'!$A$6,"") -> Lumen IT | B32: =IF('Partner Competency Input'!AK6<>"",'Partner Competency Input'!$B$6,"") -> Craig Tamlin | C32: =IF('Partner Competency Input'!AK6<>"",'Partner Competency Input'!$D$6,"") -> Australia | D32: ='Partner Competency Input'!AK6 -> Email DLP | E32: ='Partner Competency Input'!AL6 -> Yes | F32: ='Partner Competency Input'!AM6 -> Yes | G32: ='Partner Competency Input'!AN6 -> No
A33: =IF('Partner Competency Input'!AO6<>"",'Partner Competency Input'!$A$6,"") -> Lumen IT | B33: =IF('Partner Competency Input'!AO6<>"",'Partner Competency Input'!$B$6,"") -> Craig Tamlin | C33: =IF('Partner Competency Input'!AO6<>"",'Partner Competency Input'!$D$6,"") -> Australia | D33: ='Partner Competency Input'!AO6 -> AEDLP | E33: ='Partner Competency Input'!AP6 -> Yes | F33: ='Partner Competency Input'!AQ6 -> Yes | G33: ='Partner Competency Input'!AR6 -> Yes
A34: =IF('Partner Competency Input'!AS6<>"",'Partner Competency Input'!$A$6,"") -> Lumen IT | B34: =IF('Partner Competency Input'!AS6<>"",'Partner Competency Input'!$B$6,"") -> Craig Tamlin | C34: =IF('Partner Competency Input'!AS6<>"",'Partner Competency Input'!$D$6,"") -> Australia | D34: ='Partner Competency Input'!AS6 -> CEPAPI | E34: ='Partner Competency Input'!AT6 -> Yes | F34: ='Partner Competency Input'!AU6 -> Yes | G34: ='Partner Competency Input'!AV6 -> Yes
A35: =IF('Partner Competency Input'!E7<>"",'Partner Competency Input'!$A$7,"") -> Lumen IT | B35: =IF('Partner Competency Input'!E7<>"",'Partner Competency Input'!$B$7,"") -> Andy Tamin | C35: =IF('Partner Competency Input'!E7<>"",'Partner Competency Input'!$D$7,"") -> Australia | D35: ='Partner Competency Input'!E7 -> Email Gateway | E35: ='Partner Competency Input'!F7 -> Yes | F35: ='Partner Competency Input'!G7 -> Yes | G35: ='Partner Competency Input'!H7 -> No
A36: =IF('Partner Competency Input'!I7<>"",'Partner Competency Input'!$A$7,"") -> Lumen IT | B36: =IF('Partner Competency Input'!I7<>"",'Partner Competency Input'!$B$7,"") -> Andy Tamin | C36: =IF('Partner Competency Input'!I7<>"",'Partner Competency Input'!$D$7,"") -> Australia | D36: ='Partner Competency Input'!I7 -> TAP | E36: ='Partner Competency Input'!J7 -> Yes | F36: ='Partner Competency Input'!K7 -> Yes | G36: ='Partner Competency Input'!L7 -> No
A37: =IF('Partner Competency Input'!M7<>"",'Partner Competency Input'!$A$7,"") -> Lumen IT | B37: =IF('Partner Competency Input'!M7<>"",'Partner Competency Input'!$B$7,"") -> Andy Tamin | C37: =IF('Partner Competency Input'!M7<>"",'Partner Competency Input'!$D$7,"") -> Australia | D37: ='Partner Competency Input'!M7 -> TRAP | E37: ='Partner Competency Input'!N7 -> Yes | F37: ='Partner Competency Input'!O7 -> Yes | G37: ='Partner Competency Input'!P7 -> No
A38: =IF('Partner Competency Input'!Q7<>"",'Partner Competency Input'!$A$7,"") -> Lumen IT | B38: =IF('Partner Competency Input'!Q7<>"",'Partner Competency Input'!$B$7,"") -> Andy Tamin | C38: =IF('Partner Competency Input'!Q7<>"",'Partner Competency Input'!$D$7,"") -> Australia | D38: ='Partner Competency Input'!Q7 -> Isolation | E38: ='Partner Competency Input'!R7 -> Yes | F38: ='Partner Competency Input'!S7 -> Yes | G38: ='Partner Competency Input'!T7 -> No
A39: =IF('Partner Competency Input'!U7<>"",'Partner Competency Input'!$A$7,"") -> Lumen IT | B39: =IF('Partner Competency Input'!U7<>"",'Partner Competency Input'!$B$7,"") -> Andy Tamin | C39: =IF('Partner Competency Input'!U7<>"",'Partner Competency Input'!$D$7,"") -> Australia | D39: ='Partner Competency Input'!U7 -> Zenguide | E39: ='Partner Competency Input'!V7 -> Yes | F39: ='Partner Competency Input'!W7 -> Yes | G39: ='Partner Competency Input'!X7 -> Yes
A40: =IF('Partner Competency Input'!Y7<>"",'Partner Competency Input'!$A$7,"") -> Lumen IT | B40: =IF('Partner Competency Input'!Y7<>"",'Partner Competency Input'!$B$7,"") -> Andy Tamin | C40: =IF('Partner Competency Input'!Y7<>"",'Partner Competency Input'!$D$7,"") -> Australia | D40: ='Partner Competency Input'!Y7 -> ITM | E40: ='Partner Competency Input'!Z7 -> Yes | F40: ='Partner Competency Input'!AA7 -> Yes | G40: ='Partner Competency Input'!AB7 -> No
...

Sheet Partner Summary
A1: Partner Summary
A3: Distinct Partners | C3: Distinct People | E3: Distinct Platform Assignments
A6: Partner Name | B6: Distinct People | C6: Platforms Covered | D6: Present People | E6: Demo People | F6: POC People

Sheet Heatmap Dashboard
A1: Partner Competency Heatmap Dashboard
A2: Counts are distinct people by partner and platform. Present, Demo, and POC are independent selections per platform.
A4: Partner | B4: Email Gateway | E4: TAP | H4: TRAP | K4: Isolation | N4: Zenguide | Q4: EFD | T4: SER | W4: ITM | Z4: Endpoint DLP | AC4: CASB | AF4: Email DLP | AI4: DSPM | AL4: AEDLP | AO4: CEPAPI
B5: Present | C5: Demo | D5: POC | E5: Present | F5: Demo | G5: POC | H5: Present | I5: Demo | J5: POC | K5: Present | L5: Demo | M5: POC | N5: Present | O5: Demo | P5: POC | Q5: Present | R5: Demo | S5: POC | T5: Present | U5: Demo | V5: POC | W5: Present | X5: Demo | Y5: POC | Z5: Present | AA5: Demo | AB5: POC | AC5: Present | AD5: Demo | AE5: POC | AF5: Present | AG5: Demo | AH5: POC | AI5: Present | AJ5: Demo | AK5: POC | AL5: Present | AM5: Demo | AN5: POC | AO5: Present | AP5: Demo | AQ5: POC
